<?xml version="1.0" ?>
<sdf version="1.6">
  <model name="easys">

    <!-- body -->
    <link name="base_link">
      <inertial>
        <mass>147.8671</mass>
        <inertia>
            <ixx>3.000000</ixx>
            <ixy>0</ixy>
            <ixz>0</ixz>
            <iyy>41.980233</iyy>
            <iyz>0</iyz>
            <izz>41.980233</izz>
        </inertia>
      </inertial>
      <collision name="main_body_buoyancy">
          <geometry>
              <box>
                  <size>2 0.3 0.246445166667</size>
              </box>
          </geometry>
      </collision>
      <visual name="body_visual">
        <geometry>
          <mesh>
            <uri>stl/easys.stl</uri>
          </mesh>
        </geometry>
      </visual>
      <!-- <collision name='collision'>
        <geometry>
          <mesh>
            <uri>stl/easys.stl</uri>
          </mesh>
        </geometry>
      </collision> -->
      <!-- <collision name="collision">
          <geometry>
              <box>
                  <size>0.1 0.1 0.1</size>
              </box>
          </geometry>
      </collision> -->
    </link>

  <!-- left down thruster -->
    <link name="left_down_thruster_link">
      <!-- <pose>0.116 0.04715 0.1215 0 0 -1.57</pose> -->
      <pose>0 0 0 0 0 0</pose>
      <inertial>
        <pose>0 0 0 0 0 0</pose>
        <mass>0.09</mass>
        <inertia>
            <ixx>0.000143971303</ixx>
            <ixy>0.000000000008</ixy>
            <ixz>-0.000000000224</ixz>
            <iyy>0.000140915448</iyy>
            <iyz>-0.000025236433</iyz>
            <izz>0.000033571862</izz>
        </inertia>
      </inertial>
      <collision name="collision">
        <geometry>
            <box>
                <size>0.03 0.1 0.03</size>
            </box>
        </geometry>
      </collision>
    </link>

    <joint name="left_down_thruster_joint" type="revolute">
      <parent>base_link</parent>
      <child>left_down_thruster_link</child>
      <pose>0.116 0.04715 0.1215 0 0 -1.57</pose>
      <axis>
        <xyz>1 0 0</xyz>
        <limit>
            <lower>-1e+12</lower>
            <upper>1e+12</upper>
            <effort>-1</effort>
            <velocity>-1</velocity>
        </limit>
      </axis>
    </joint>

    <!-- right down thruster -->
    <link name="right_down_thruster_link">
      <pose>0 0 0 0 0 0</pose>
      <inertial>
          <pose>0 0 0 0 0 0</pose>
          <mass>0.09</mass>
          <inertia>
              <ixx>0.000143971303</ixx>
              <ixy>0.000000000008</ixy>
              <ixz>-0.000000000224</ixz>
              <iyy>0.000140915448</iyy>
              <iyz>-0.000025236433</iyz>
              <izz>0.000033571862</izz>
          </inertia>
      </inertial>
      <collision name="collision">
          <geometry>
              <box>
                <size>0.03 0.1 0.03</size>
              </box>
          </geometry>
      </collision>
    </link>

    <joint name="right_down_thruster_joint" type="revolute">
      <parent>base_link</parent>
      <child>right_down_thruster_link</child>
      <pose>-0.116 0.04715 0.1215 0 0 -1.57</pose>
      <axis>
        <xyz>1 0 0</xyz>
        <limit>
            <lower>-1e+12</lower>
            <upper>1e+12</upper>
            <effort>-1</effort>
            <velocity>-1</velocity>
        </limit>
      </axis>
    </joint>

    <!-- left up thruster -->
    <link name="left_up_thruster_link">
      <pose>0 0 0 0 0 0</pose>
      <inertial>
          <pose>0 0 0 0 0 0</pose>
          <mass>0.09</mass>
          <inertia>
              <ixx>0.000143971303</ixx>
              <ixy>0.000000000008</ixy>
              <ixz>-0.000000000224</ixz>
              <iyy>0.000140915448</iyy>
              <iyz>-0.000025236433</iyz>
              <izz>0.000033571862</izz>
          </inertia>
      </inertial>
      <collision name="collision">
          <geometry>
              <box>
                <size>0.03 0.1 0.03</size>
              </box>
          </geometry>
      </collision>
    </link>

    <joint name="left_up_thruster_joint" type="revolute">
      <parent>base_link</parent>
      <child>left_up_thruster_link</child>
      <pose>0.08255 0 0.22255 0 0.785 0</pose>
      <axis>
        <xyz>1 0 0</xyz>
        <limit>
            <lower>-1e+12</lower>
            <upper>1e+12</upper>
            <effort>-1</effort>
            <velocity>-1</velocity>
        </limit>
      </axis>
    </joint>
    
    <!-- right up thruster -->
    <link name="right_up_thruster_link">
      <pose>0 0 0 0 0 0</pose>
      <inertial>
          <pose>0 0 0 0 0 0</pose>
          <mass>0.09</mass>
          <inertia>
              <ixx>0.000143971303</ixx>
              <ixy>0.000000000008</ixy>
              <ixz>-0.000000000224</ixz>
              <iyy>0.000140915448</iyy>
              <iyz>-0.000025236433</iyz>
              <izz>0.000033571862</izz>
          </inertia>
      </inertial>
      <collision name="collision">
          <geometry>
              <box>
                <size>0.03 0.1 0.03</size>
              </box>
          </geometry>
      </collision>
    </link>

    <joint name="right_up_thruster_joint" type="revolute">
      <parent>base_link</parent>
      <child>right_up_thruster_link</child>
      <pose>-0.08255 0 0.22255 0 0.785 3.14</pose>
      <axis>
        <xyz>1 0 0</xyz>
        <limit>
            <lower>-1e+12</lower>
            <upper>1e+12</upper>
            <effort>-1</effort>
            <velocity>-1</velocity>
        </limit>
      </axis>
    </joint>
  </model>

  
</sdf>
